2021-11-07 14:29:49,182 INFO: Blog startup [in /Users/alenakapustan/Git/web_app/blog.py:23]
2021-11-07 14:30:40,193 ERROR: Exception on /edit_profile [POST] [in /Users/alenakapustan/Git/web_app/.venv/lib/python3.8/site-packages/flask/app.py:1457]
Traceback (most recent call last):
  File "/Users/alenakapustan/Git/web_app/.venv/lib/python3.8/site-packages/sqlalchemy/engine/base.py", line 1799, in _execute_context
    self.dialect.do_execute(
  File "/Users/alenakapustan/Git/web_app/.venv/lib/python3.8/site-packages/sqlalchemy/engine/default.py", line 717, in do_execute
    cursor.execute(statement, parameters)
  File "/Users/alenakapustan/Git/web_app/.venv/lib/python3.8/site-packages/pymysql/cursors.py", line 148, in execute
    result = self._query(query)
  File "/Users/alenakapustan/Git/web_app/.venv/lib/python3.8/site-packages/pymysql/cursors.py", line 310, in _query
    conn.query(q)
  File "/Users/alenakapustan/Git/web_app/.venv/lib/python3.8/site-packages/pymysql/connections.py", line 548, in query
    self._affected_rows = self._read_query_result(unbuffered=unbuffered)
  File "/Users/alenakapustan/Git/web_app/.venv/lib/python3.8/site-packages/pymysql/connections.py", line 775, in _read_query_result
    result.read()
  File "/Users/alenakapustan/Git/web_app/.venv/lib/python3.8/site-packages/pymysql/connections.py", line 1156, in read
    first_packet = self.connection._read_packet()
  File "/Users/alenakapustan/Git/web_app/.venv/lib/python3.8/site-packages/pymysql/connections.py", line 725, in _read_packet
    packet.raise_for_error()
  File "/Users/alenakapustan/Git/web_app/.venv/lib/python3.8/site-packages/pymysql/protocol.py", line 221, in raise_for_error
    err.raise_mysql_exception(self._data)
  File "/Users/alenakapustan/Git/web_app/.venv/lib/python3.8/site-packages/pymysql/err.py", line 143, in raise_mysql_exception
    raise errorclass(errno, errval)
pymysql.err.IntegrityError: (1062, "Duplicate entry 'alinka' for key 'user.ix_user_nickname'")

The above exception was the direct cause of the following exception:

Traceback (most recent call last):
  File "/Users/alenakapustan/Git/web_app/.venv/lib/python3.8/site-packages/flask/app.py", line 2073, in wsgi_app
    response = self.full_dispatch_request()
  File "/Users/alenakapustan/Git/web_app/.venv/lib/python3.8/site-packages/flask/app.py", line 1518, in full_dispatch_request
    rv = self.handle_user_exception(e)
  File "/Users/alenakapustan/Git/web_app/.venv/lib/python3.8/site-packages/flask/app.py", line 1516, in full_dispatch_request
    rv = self.dispatch_request()
  File "/Users/alenakapustan/Git/web_app/.venv/lib/python3.8/site-packages/flask/app.py", line 1502, in dispatch_request
    return self.ensure_sync(self.view_functions[rule.endpoint])(**req.view_args)
  File "/Users/alenakapustan/Git/web_app/.venv/lib/python3.8/site-packages/flask_login/utils.py", line 272, in decorated_view
    return func(*args, **kwargs)
  File "/Users/alenakapustan/Git/web_app/app/view.py", line 83, in edit_profile
    db.session.commit()
  File "<string>", line 2, in commit
  File "/Users/alenakapustan/Git/web_app/.venv/lib/python3.8/site-packages/sqlalchemy/orm/session.py", line 1428, in commit
    self._transaction.commit(_to_root=self.future)
  File "/Users/alenakapustan/Git/web_app/.venv/lib/python3.8/site-packages/sqlalchemy/orm/session.py", line 829, in commit
    self._prepare_impl()
  File "/Users/alenakapustan/Git/web_app/.venv/lib/python3.8/site-packages/sqlalchemy/orm/session.py", line 808, in _prepare_impl
    self.session.flush()
  File "/Users/alenakapustan/Git/web_app/.venv/lib/python3.8/site-packages/sqlalchemy/orm/session.py", line 3340, in flush
    self._flush(objects)
  File "/Users/alenakapustan/Git/web_app/.venv/lib/python3.8/site-packages/sqlalchemy/orm/session.py", line 3480, in _flush
    transaction.rollback(_capture_exception=True)
  File "/Users/alenakapustan/Git/web_app/.venv/lib/python3.8/site-packages/sqlalchemy/util/langhelpers.py", line 70, in __exit__
    compat.raise_(
  File "/Users/alenakapustan/Git/web_app/.venv/lib/python3.8/site-packages/sqlalchemy/util/compat.py", line 207, in raise_
    raise exception
  File "/Users/alenakapustan/Git/web_app/.venv/lib/python3.8/site-packages/sqlalchemy/orm/session.py", line 3440, in _flush
    flush_context.execute()
  File "/Users/alenakapustan/Git/web_app/.venv/lib/python3.8/site-packages/sqlalchemy/orm/unitofwork.py", line 456, in execute
    rec.execute(self)
  File "/Users/alenakapustan/Git/web_app/.venv/lib/python3.8/site-packages/sqlalchemy/orm/unitofwork.py", line 630, in execute
    util.preloaded.orm_persistence.save_obj(
  File "/Users/alenakapustan/Git/web_app/.venv/lib/python3.8/site-packages/sqlalchemy/orm/persistence.py", line 236, in save_obj
    _emit_update_statements(
  File "/Users/alenakapustan/Git/web_app/.venv/lib/python3.8/site-packages/sqlalchemy/orm/persistence.py", line 1000, in _emit_update_statements
    c = connection._execute_20(
  File "/Users/alenakapustan/Git/web_app/.venv/lib/python3.8/site-packages/sqlalchemy/engine/base.py", line 1611, in _execute_20
    return meth(self, args_10style, kwargs_10style, execution_options)
  File "/Users/alenakapustan/Git/web_app/.venv/lib/python3.8/site-packages/sqlalchemy/sql/elements.py", line 325, in _execute_on_connection
    return connection._execute_clauseelement(
  File "/Users/alenakapustan/Git/web_app/.venv/lib/python3.8/site-packages/sqlalchemy/engine/base.py", line 1478, in _execute_clauseelement
    ret = self._execute_context(
  File "/Users/alenakapustan/Git/web_app/.venv/lib/python3.8/site-packages/sqlalchemy/engine/base.py", line 1842, in _execute_context
    self._handle_dbapi_exception(
  File "/Users/alenakapustan/Git/web_app/.venv/lib/python3.8/site-packages/sqlalchemy/engine/base.py", line 2023, in _handle_dbapi_exception
    util.raise_(
  File "/Users/alenakapustan/Git/web_app/.venv/lib/python3.8/site-packages/sqlalchemy/util/compat.py", line 207, in raise_
    raise exception
  File "/Users/alenakapustan/Git/web_app/.venv/lib/python3.8/site-packages/sqlalchemy/engine/base.py", line 1799, in _execute_context
    self.dialect.do_execute(
  File "/Users/alenakapustan/Git/web_app/.venv/lib/python3.8/site-packages/sqlalchemy/engine/default.py", line 717, in do_execute
    cursor.execute(statement, parameters)
  File "/Users/alenakapustan/Git/web_app/.venv/lib/python3.8/site-packages/pymysql/cursors.py", line 148, in execute
    result = self._query(query)
  File "/Users/alenakapustan/Git/web_app/.venv/lib/python3.8/site-packages/pymysql/cursors.py", line 310, in _query
    conn.query(q)
  File "/Users/alenakapustan/Git/web_app/.venv/lib/python3.8/site-packages/pymysql/connections.py", line 548, in query
    self._affected_rows = self._read_query_result(unbuffered=unbuffered)
  File "/Users/alenakapustan/Git/web_app/.venv/lib/python3.8/site-packages/pymysql/connections.py", line 775, in _read_query_result
    result.read()
  File "/Users/alenakapustan/Git/web_app/.venv/lib/python3.8/site-packages/pymysql/connections.py", line 1156, in read
    first_packet = self.connection._read_packet()
  File "/Users/alenakapustan/Git/web_app/.venv/lib/python3.8/site-packages/pymysql/connections.py", line 725, in _read_packet
    packet.raise_for_error()
  File "/Users/alenakapustan/Git/web_app/.venv/lib/python3.8/site-packages/pymysql/protocol.py", line 221, in raise_for_error
    err.raise_mysql_exception(self._data)
  File "/Users/alenakapustan/Git/web_app/.venv/lib/python3.8/site-packages/pymysql/err.py", line 143, in raise_mysql_exception
    raise errorclass(errno, errval)
sqlalchemy.exc.IntegrityError: (pymysql.err.IntegrityError) (1062, "Duplicate entry 'alinka' for key 'user.ix_user_nickname'")
[SQL: UPDATE user SET nickname=%(nickname)s, about_me=%(about_me)s, updated=%(updated)s WHERE user.id = %(user_id)s]
[parameters: {'nickname': 'alinka', 'about_me': "Hi, my name is Alena, and i'm very like to travel. Traveling fills our life with bright colors and emotions!", 'updated': datetime.datetime(2021, 11, 7, 11, 30, 40, 191041), 'user_id': 5}]
(Background on this error at: https://sqlalche.me/e/14/gkpj)
2021-11-07 14:33:59,247 INFO: Blog startup [in /Users/alenakapustan/Git/web_app/blog.py:23]
2022-03-22 14:16:40,473 INFO: Blog startup [in /Users/alenak/Projects/web_app/blog.py:23]
