2022-03-22 14:17:05,985 ERROR: Exception on / [GET] [in /Users/alenak/.local/share/virtualenvs/web_app-CmvQIF_o/lib/python3.9/site-packages/flask/app.py:1457]
Traceback (most recent call last):
  File "/Users/alenak/.local/share/virtualenvs/web_app-CmvQIF_o/lib/python3.9/site-packages/sqlalchemy/util/_collections.py", line 1008, in __call__
    return self.registry[key]
KeyError: 6111457280

During handling of the above exception, another exception occurred:

Traceback (most recent call last):
  File "/Users/alenak/.local/share/virtualenvs/web_app-CmvQIF_o/lib/python3.9/site-packages/flask/app.py", line 2073, in wsgi_app
    response = self.full_dispatch_request()
  File "/Users/alenak/.local/share/virtualenvs/web_app-CmvQIF_o/lib/python3.9/site-packages/flask/app.py", line 1518, in full_dispatch_request
    rv = self.handle_user_exception(e)
  File "/Users/alenak/.local/share/virtualenvs/web_app-CmvQIF_o/lib/python3.9/site-packages/flask/app.py", line 1516, in full_dispatch_request
    rv = self.dispatch_request()
  File "/Users/alenak/.local/share/virtualenvs/web_app-CmvQIF_o/lib/python3.9/site-packages/flask/app.py", line 1502, in dispatch_request
    return self.ensure_sync(self.view_functions[rule.endpoint])(**req.view_args)
  File "/Users/alenak/Projects/web_app/app/view.py", line 46, in index
    posts = Post.query.order_by(Post.created.desc())
  File "/Users/alenak/.local/share/virtualenvs/web_app-CmvQIF_o/lib/python3.9/site-packages/flask_sqlalchemy/__init__.py", line 552, in __get__
    return type.query_class(mapper, session=self.sa.session())
  File "/Users/alenak/.local/share/virtualenvs/web_app-CmvQIF_o/lib/python3.9/site-packages/sqlalchemy/orm/scoping.py", line 47, in __call__
    sess = self.registry()
  File "/Users/alenak/.local/share/virtualenvs/web_app-CmvQIF_o/lib/python3.9/site-packages/sqlalchemy/util/_collections.py", line 1010, in __call__
    return self.registry.setdefault(key, self.createfunc())
  File "/Users/alenak/.local/share/virtualenvs/web_app-CmvQIF_o/lib/python3.9/site-packages/sqlalchemy/orm/session.py", line 4205, in __call__
    return self.class_(**local_kw)
  File "/Users/alenak/.local/share/virtualenvs/web_app-CmvQIF_o/lib/python3.9/site-packages/flask_sqlalchemy/__init__.py", line 176, in __init__
    bind = options.pop('bind', None) or db.engine
  File "/Users/alenak/.local/share/virtualenvs/web_app-CmvQIF_o/lib/python3.9/site-packages/flask_sqlalchemy/__init__.py", line 998, in engine
    return self.get_engine()
  File "/Users/alenak/.local/share/virtualenvs/web_app-CmvQIF_o/lib/python3.9/site-packages/flask_sqlalchemy/__init__.py", line 1017, in get_engine
    return connector.get_engine()
  File "/Users/alenak/.local/share/virtualenvs/web_app-CmvQIF_o/lib/python3.9/site-packages/flask_sqlalchemy/__init__.py", line 593, in get_engine
    sa_url, options = self.get_options(sa_url, echo)
  File "/Users/alenak/.local/share/virtualenvs/web_app-CmvQIF_o/lib/python3.9/site-packages/flask_sqlalchemy/__init__.py", line 608, in get_options
    sa_url, options = self._sa.apply_driver_hacks(self._app, sa_url, options)
  File "/Users/alenak/.local/share/virtualenvs/web_app-CmvQIF_o/lib/python3.9/site-packages/flask_sqlalchemy/__init__.py", line 933, in apply_driver_hacks
    if sa_url.drivername.startswith('mysql'):
AttributeError: 'NoneType' object has no attribute 'drivername'
2022-03-22 14:17:08,240 ERROR: Exception on / [GET] [in /Users/alenak/.local/share/virtualenvs/web_app-CmvQIF_o/lib/python3.9/site-packages/flask/app.py:1457]
Traceback (most recent call last):
  File "/Users/alenak/.local/share/virtualenvs/web_app-CmvQIF_o/lib/python3.9/site-packages/sqlalchemy/util/_collections.py", line 1008, in __call__
    return self.registry[key]
KeyError: 6111457280

During handling of the above exception, another exception occurred:

Traceback (most recent call last):
  File "/Users/alenak/.local/share/virtualenvs/web_app-CmvQIF_o/lib/python3.9/site-packages/flask/app.py", line 2073, in wsgi_app
    response = self.full_dispatch_request()
  File "/Users/alenak/.local/share/virtualenvs/web_app-CmvQIF_o/lib/python3.9/site-packages/flask/app.py", line 1518, in full_dispatch_request
    rv = self.handle_user_exception(e)
  File "/Users/alenak/.local/share/virtualenvs/web_app-CmvQIF_o/lib/python3.9/site-packages/flask/app.py", line 1516, in full_dispatch_request
    rv = self.dispatch_request()
  File "/Users/alenak/.local/share/virtualenvs/web_app-CmvQIF_o/lib/python3.9/site-packages/flask/app.py", line 1502, in dispatch_request
    return self.ensure_sync(self.view_functions[rule.endpoint])(**req.view_args)
  File "/Users/alenak/Projects/web_app/app/view.py", line 46, in index
    posts = Post.query.order_by(Post.created.desc())
  File "/Users/alenak/.local/share/virtualenvs/web_app-CmvQIF_o/lib/python3.9/site-packages/flask_sqlalchemy/__init__.py", line 552, in __get__
    return type.query_class(mapper, session=self.sa.session())
  File "/Users/alenak/.local/share/virtualenvs/web_app-CmvQIF_o/lib/python3.9/site-packages/sqlalchemy/orm/scoping.py", line 47, in __call__
    sess = self.registry()
  File "/Users/alenak/.local/share/virtualenvs/web_app-CmvQIF_o/lib/python3.9/site-packages/sqlalchemy/util/_collections.py", line 1010, in __call__
    return self.registry.setdefault(key, self.createfunc())
  File "/Users/alenak/.local/share/virtualenvs/web_app-CmvQIF_o/lib/python3.9/site-packages/sqlalchemy/orm/session.py", line 4205, in __call__
    return self.class_(**local_kw)
  File "/Users/alenak/.local/share/virtualenvs/web_app-CmvQIF_o/lib/python3.9/site-packages/flask_sqlalchemy/__init__.py", line 176, in __init__
    bind = options.pop('bind', None) or db.engine
  File "/Users/alenak/.local/share/virtualenvs/web_app-CmvQIF_o/lib/python3.9/site-packages/flask_sqlalchemy/__init__.py", line 998, in engine
    return self.get_engine()
  File "/Users/alenak/.local/share/virtualenvs/web_app-CmvQIF_o/lib/python3.9/site-packages/flask_sqlalchemy/__init__.py", line 1017, in get_engine
    return connector.get_engine()
  File "/Users/alenak/.local/share/virtualenvs/web_app-CmvQIF_o/lib/python3.9/site-packages/flask_sqlalchemy/__init__.py", line 593, in get_engine
    sa_url, options = self.get_options(sa_url, echo)
  File "/Users/alenak/.local/share/virtualenvs/web_app-CmvQIF_o/lib/python3.9/site-packages/flask_sqlalchemy/__init__.py", line 608, in get_options
    sa_url, options = self._sa.apply_driver_hacks(self._app, sa_url, options)
  File "/Users/alenak/.local/share/virtualenvs/web_app-CmvQIF_o/lib/python3.9/site-packages/flask_sqlalchemy/__init__.py", line 933, in apply_driver_hacks
    if sa_url.drivername.startswith('mysql'):
AttributeError: 'NoneType' object has no attribute 'drivername'
