[2022-06-04 19:24:38,496] ERROR: (psycopg2.errors.NotNullViolation) null value in column "title" of relation "post" violates not-null constraint
DETAIL:  Failing row contains (6, null, null, wayyyy, 1, default.jpeg, 2022-06-04 16:24:38.494477, 2022-06-04 16:24:38.494486).

[SQL: INSERT INTO post (post_id, title, intro, text, user_id, picture_file, created, updated) VALUES (%(post_id)s, %(title)s, %(intro)s, %(text)s, %(user_id)s, %(picture_file)s, %(created)s, %(updated)s)]
[parameters: {'post_id': 6, 'title': None, 'intro': None, 'text': 'wayyyy', 'user_id': 1, 'picture_file': 'default.jpeg', 'created': datetime.datetime(2022, 6, 4, 16, 24, 38, 494477), 'updated': datetime.datetime(2022, 6, 4, 16, 24, 38, 494486)}]
(Background on this error at: https://sqlalche.me/e/14/gkpj)
Traceback (most recent call last):
  File "/Users/alenak/.local/share/virtualenvs/web_app-CmvQIF_o/lib/python3.10/site-packages/sqlalchemy/engine/base.py", line 1819, in _execute_context
    self.dialect.do_execute(
  File "/Users/alenak/.local/share/virtualenvs/web_app-CmvQIF_o/lib/python3.10/site-packages/sqlalchemy/engine/default.py", line 732, in do_execute
    cursor.execute(statement, parameters)
psycopg2.errors.NotNullViolation: null value in column "title" of relation "post" violates not-null constraint
DETAIL:  Failing row contains (6, null, null, wayyyy, 1, default.jpeg, 2022-06-04 16:24:38.494477, 2022-06-04 16:24:38.494486).


The above exception was the direct cause of the following exception:

Traceback (most recent call last):
  File "/Users/alenak/Projects/web_app/app/posts/views.py", line 67, in single_post
    app.servises.post_service.save(comment)
  File "/Users/alenak/Projects/web_app/app/core.py", line 38, in save
    db.session.commit()
  File "<string>", line 2, in commit
  File "/Users/alenak/.local/share/virtualenvs/web_app-CmvQIF_o/lib/python3.10/site-packages/sqlalchemy/orm/session.py", line 1451, in commit
    self._transaction.commit(_to_root=self.future)
  File "/Users/alenak/.local/share/virtualenvs/web_app-CmvQIF_o/lib/python3.10/site-packages/sqlalchemy/orm/session.py", line 829, in commit
    self._prepare_impl()
  File "/Users/alenak/.local/share/virtualenvs/web_app-CmvQIF_o/lib/python3.10/site-packages/sqlalchemy/orm/session.py", line 808, in _prepare_impl
    self.session.flush()
  File "/Users/alenak/.local/share/virtualenvs/web_app-CmvQIF_o/lib/python3.10/site-packages/sqlalchemy/orm/session.py", line 3383, in flush
    self._flush(objects)
  File "/Users/alenak/.local/share/virtualenvs/web_app-CmvQIF_o/lib/python3.10/site-packages/sqlalchemy/orm/session.py", line 3522, in _flush
    with util.safe_reraise():
  File "/Users/alenak/.local/share/virtualenvs/web_app-CmvQIF_o/lib/python3.10/site-packages/sqlalchemy/util/langhelpers.py", line 70, in __exit__
    compat.raise_(
  File "/Users/alenak/.local/share/virtualenvs/web_app-CmvQIF_o/lib/python3.10/site-packages/sqlalchemy/util/compat.py", line 208, in raise_
    raise exception
  File "/Users/alenak/.local/share/virtualenvs/web_app-CmvQIF_o/lib/python3.10/site-packages/sqlalchemy/orm/session.py", line 3483, in _flush
    flush_context.execute()
  File "/Users/alenak/.local/share/virtualenvs/web_app-CmvQIF_o/lib/python3.10/site-packages/sqlalchemy/orm/unitofwork.py", line 456, in execute
    rec.execute(self)
  File "/Users/alenak/.local/share/virtualenvs/web_app-CmvQIF_o/lib/python3.10/site-packages/sqlalchemy/orm/unitofwork.py", line 630, in execute
    util.preloaded.orm_persistence.save_obj(
  File "/Users/alenak/.local/share/virtualenvs/web_app-CmvQIF_o/lib/python3.10/site-packages/sqlalchemy/orm/persistence.py", line 245, in save_obj
    _emit_insert_statements(
  File "/Users/alenak/.local/share/virtualenvs/web_app-CmvQIF_o/lib/python3.10/site-packages/sqlalchemy/orm/persistence.py", line 1097, in _emit_insert_statements
    c = connection._execute_20(
  File "/Users/alenak/.local/share/virtualenvs/web_app-CmvQIF_o/lib/python3.10/site-packages/sqlalchemy/engine/base.py", line 1631, in _execute_20
    return meth(self, args_10style, kwargs_10style, execution_options)
  File "/Users/alenak/.local/share/virtualenvs/web_app-CmvQIF_o/lib/python3.10/site-packages/sqlalchemy/sql/elements.py", line 325, in _execute_on_connection
    return connection._execute_clauseelement(
  File "/Users/alenak/.local/share/virtualenvs/web_app-CmvQIF_o/lib/python3.10/site-packages/sqlalchemy/engine/base.py", line 1498, in _execute_clauseelement
    ret = self._execute_context(
  File "/Users/alenak/.local/share/virtualenvs/web_app-CmvQIF_o/lib/python3.10/site-packages/sqlalchemy/engine/base.py", line 1862, in _execute_context
    self._handle_dbapi_exception(
  File "/Users/alenak/.local/share/virtualenvs/web_app-CmvQIF_o/lib/python3.10/site-packages/sqlalchemy/engine/base.py", line 2043, in _handle_dbapi_exception
    util.raise_(
  File "/Users/alenak/.local/share/virtualenvs/web_app-CmvQIF_o/lib/python3.10/site-packages/sqlalchemy/util/compat.py", line 208, in raise_
    raise exception
  File "/Users/alenak/.local/share/virtualenvs/web_app-CmvQIF_o/lib/python3.10/site-packages/sqlalchemy/engine/base.py", line 1819, in _execute_context
    self.dialect.do_execute(
  File "/Users/alenak/.local/share/virtualenvs/web_app-CmvQIF_o/lib/python3.10/site-packages/sqlalchemy/engine/default.py", line 732, in do_execute
    cursor.execute(statement, parameters)
sqlalchemy.exc.IntegrityError: (psycopg2.errors.NotNullViolation) null value in column "title" of relation "post" violates not-null constraint
DETAIL:  Failing row contains (6, null, null, wayyyy, 1, default.jpeg, 2022-06-04 16:24:38.494477, 2022-06-04 16:24:38.494486).

[SQL: INSERT INTO post (post_id, title, intro, text, user_id, picture_file, created, updated) VALUES (%(post_id)s, %(title)s, %(intro)s, %(text)s, %(user_id)s, %(picture_file)s, %(created)s, %(updated)s)]
[parameters: {'post_id': 6, 'title': None, 'intro': None, 'text': 'wayyyy', 'user_id': 1, 'picture_file': 'default.jpeg', 'created': datetime.datetime(2022, 6, 4, 16, 24, 38, 494477), 'updated': datetime.datetime(2022, 6, 4, 16, 24, 38, 494486)}]
(Background on this error at: https://sqlalche.me/e/14/gkpj)
[2022-06-04 19:27:09,754] WARNING: An error occurred while saving data (add new comment)
[2022-06-04 19:27:09,754] ERROR: <None:wayyyy!> is not of type <class 'app.posts.models.Post'>
Traceback (most recent call last):
  File "/Users/alenak/Projects/web_app/app/posts/views.py", line 67, in single_post
    app.servises.post_service.save(comment)
  File "/Users/alenak/Projects/web_app/app/core.py", line 36, in save
    self._isinstance(model)
  File "/Users/alenak/Projects/web_app/app/core.py", line 21, in _isinstance
    raise ValueError('%s is not of type %s' % (model, self.__model__))
ValueError: <None:wayyyy!> is not of type <class 'app.posts.models.Post'>
[2022-06-04 19:27:52,276] INFO: User admin added new comment.
[2022-06-05 12:31:42,930] INFO: User admin logged in.
[2022-06-05 12:35:34,836] INFO: User ami logged in.
[2022-06-05 12:39:03,001] INFO: User ami logged in.
[2022-06-05 12:42:31,662] INFO: User admin logged in.
